<?xml version="1.0"?>
<robot name="qutee_robot">

    <!-- 
        axes information-
                        positive / negative
        x-axis(red)  :  forwards / backwards 
        y-axis(green):  left     / right 
        z-axis(blue) :  up       / down
        (from the robots point of view)
        colours are axes as seen in rviz

        positive joint rotation results in a clockwise motor drive when viewed from above the motor

        dimensions are in meters
    -->

    <material name="grey">
        <color rgba="0.7 0.7 0.7 1"/>
    </material>

    <material name="green">
        <color rgba="0 0.6 0 1"/>
    </material>

    <material name="black">
        <color rgba="0 0 0 1"/>
    </material>

    <material name="blue">
        <color rgba="0 0 1 1"/>
    </material>

    <!-- <link name="world_link" />
    
    <joint name="world_base_footprint_joint" type="fixed">
        <parent link="world_link"/>
        <child link="base_footprint_link"/>
        <origin xyz="0 0 0" rpy="0 0 0"/>
    </joint>

    <link name="base_footprint_link" /> -->
        
    <!-- <joint name="base_joint" type="fixed">
        <parent link="base_footprint_link"/>
        <child link="base_link"/>
        <origin xyz="0 0 0" rpy="0 0 0"/>
    </joint> -->


    <!-- represents the battery box as seen in the assembly stl (refer to fusion360) -->
    <link name="base_link">
        <visual>
            <geometry>
                <box size="0.035 0.034 0.03"/>
            </geometry>
            <origin xyz="0 0 0" rpy="0 0 0"/>
            <material name="grey"/>
        </visual>
    </link>


    <!-- body bottom (lower base) ////////////////////////////////////////////////////////////////////////////////// -->
    <joint name="body_bt_sq_joint" type="fixed">
        <parent link="base_link"/>
        <child link="body_bottom_sq_link"/>
        <origin xyz="0 0 -0.0145" rpy="0 0 0"/>
    </joint>

    <!-- top of body bottom is 0.031 down from top of battery box -->
    <!-- overall dimensions of bottom base is 0.114 x 0.114 x 0.002, but corners are constructed from cylinders -->
    <link name="body_bottom_sq_link">

        <!-- square center -->
        <visual>
            <geometry>
                <box size="0.078 0.078 0.002"/>
            </geometry>
            <origin xyz="0 0 0" rpy="0 0 0.7854"/>
            <material name="green"/>
        </visual>

        <!-- front corner -->
        <visual>
            <geometry>
                <cylinder radius="0.014" length="0.002"/>
            </geometry>
            <origin xyz="0.043 0 0" rpy="0 0 0"/>
            <material name="green"/>
        </visual>

        <!-- rear corner -->
        <visual>
            <geometry>
                <cylinder radius="0.014" length="0.002"/>
            </geometry>
            <origin xyz="-0.043 0 0" rpy="0 0 0"/>
            <material name="green"/>
        </visual>

        <!-- left corner -->
        <visual>
            <geometry>
                <cylinder radius="0.014" length="0.002"/>
            </geometry>
            <origin xyz="0 0.043 0" rpy="0 0 0"/>
            <material name="green"/>
        </visual>

        <!-- right corner -->
        <visual>
            <geometry>
                <cylinder radius="0.014" length="0.002"/>
            </geometry>
            <origin xyz="0 -0.043 0" rpy="0 0 0"/>
            <material name="green"/>
        </visual>
    </link>


    <!-- body base (top base) ////////////////////////////////////////////////////////////////////////////////// -->
    <joint name="body_base_sq_joint" type="fixed">
        <parent link="base_link"/>
        <child link="body_base_sq_link"/>
        <origin xyz="0 0 0.0115" rpy="0 0 0"/>
    </joint>

    <!-- bottom of body base is 0.028 up from bottom of battery box -->
    <!-- overall dimensions of bottom base is 0.114 x 0.114 x 0.002, but corners are constructed from cylinders -->
    <link name="body_base_sq_link">

        <!-- square center -->
        <visual>
            <geometry>
                <box size="0.078 0.078 0.002"/>
            </geometry>
            <origin xyz="0 0 0" rpy="0 0 0.7854"/>
            <material name="green"/>
        </visual>

        <!-- front corner -->
        <visual>
            <geometry>
                <cylinder radius="0.014" length="0.002"/>
            </geometry>
            <origin xyz="0.043 0 0" rpy="0 0 0"/>
            <material name="green"/>
        </visual>

        <!-- rear corner -->
        <visual>
            <geometry>
                <cylinder radius="0.014" length="0.002"/>
            </geometry>
            <origin xyz="-0.043 0 0" rpy="0 0 0"/>
            <material name="green"/>
        </visual>

        <!-- left corner -->
        <visual>
            <geometry>
                <cylinder radius="0.014" length="0.002"/>
            </geometry>
            <origin xyz="0 0.043 0" rpy="0 0 0"/>
            <material name="green"/>
        </visual>

        <!-- right corner -->
        <visual>
            <geometry>
                <cylinder radius="0.014" length="0.002"/>
            </geometry>
            <origin xyz="0 -0.043 0" rpy="0 0 0"/>
            <material name="green"/>
        </visual>
    </link>


    <!-- top case ////////////////////////////////////////////////////////////////////////////////// -->
    <joint name="body_base_sq_top_case_joint" type="fixed">
        <parent link="body_base_sq_link"/>
        <child link="top_case_link"/>
        <origin xyz="0 0 0.01055" rpy="0 0 0"/>
    </joint>

    <link name="top_case_link">
        <!-- horizontal components -->
        <visual>
            <geometry>
                <box size="0.0085 0.0544 0.0055"/>
            </geometry>
            <origin xyz="-0.0259 0 0.0091" rpy="0 0 0"/>
            <material name="black"/>        
        </visual>
        <visual>
            <geometry>
                <box size="0.0021 0.0544 0.002"/>
            </geometry>
            <origin xyz="-0.0024 0 0.01085" rpy="0 0 0"/>
            <material name="black"/>        
        </visual>
        <visual>
            <geometry>
                <box size="0.0336 0.0394 0.002"/>
            </geometry>
            <origin xyz="0.01335 0.0075 0.01085" rpy="0 0 0"/>
            <material name="black"/>        
        </visual>
        <visual>
            <geometry>
                <box size="0.0086 0.0544 0.0055"/>
            </geometry>
            <origin xyz="0.02585 0 0.0091" rpy="0 0 0"/>
            <material name="black"/>        
        </visual>
        <visual>
            <geometry>
                <box size="0.0603 0.0056 0.0055"/>
            </geometry>
            <origin xyz="0 0.0244 0.0091" rpy="0 0 0"/>
            <material name="black"/>        
        </visual>
        <visual>
            <geometry>
                <box size="0.0603 0.0055 0.0055"/>
            </geometry>
            <origin xyz="0 -0.02445 0.0091" rpy="0 0 0"/>
            <material name="black"/>        
        </visual>

        <!-- corners -->
        <visual>
            <geometry>
                <cylinder radius="0.0126" length="0.0237"/>
            </geometry>
            <origin xyz="0.0274 0.02445 0" rpy="0 0 0"/>
            <material name="black"/>        
        </visual>
        <visual>
            <geometry>
                <cylinder radius="0.0126" length="0.0237"/>
            </geometry>
            <origin xyz="-0.0274 0.02445 0" rpy="0 0 0"/>
            <material name="black"/>        
        </visual>
        <visual>
            <geometry>
                <cylinder radius="0.0126" length="0.0237"/>
            </geometry>
            <origin xyz="0.0274 -0.02445 0" rpy="0 0 0"/>
            <material name="black"/>        
        </visual>
        <visual>
            <geometry>
                <cylinder radius="0.0126" length="0.0237"/>
            </geometry>
            <origin xyz="-0.0274 -0.02445 0" rpy="0 0 0"/>
            <material name="black"/>        
        </visual>
    </link>


    <!-- bottom case ////////////////////////////////////////////////////////////////////////////////// -->
    <joint name="body_bottom_sq_bottom_case_joint" type="fixed">
        <parent link="body_bottom_sq_link"/>
        <child link="bottom_case_link"/>
        <origin xyz="0 0 -0.0089" rpy="0 0 0"/>
    </joint>

    <link name="bottom_case_link">
        <!-- horizontal components -->
        <visual>
            <geometry>
                <box size="0.0630 0.057 0.0035"/>
            </geometry>
            <origin xyz="0 0 -0.0101" rpy="0 0 0"/>
            <material name="black"/>
        </visual>
        <visual>
            <geometry>
                <box size="0.003 0.057 0.0082"/>
            </geometry>
            <origin xyz="0.03 0 -0.00775" rpy="0 0 0"/>
            <material name="black"/>
        </visual>
        <visual>
            <geometry>
                <box size="0.003 0.057 0.0082"/>
            </geometry>
            <origin xyz="-0.03 0 -0.00775" rpy="0 0 0"/>
            <material name="black"/>
        </visual>
        <visual>
            <geometry>
                <box size="0.0630 0.003 0.0082"/>
            </geometry>
            <origin xyz="0 0.027 -0.00775" rpy="0 0 0"/>
            <material name="black"/>
        </visual>
        <visual>
            <geometry>
                <box size="0.0630 0.003 0.0082"/>
            </geometry>
            <origin xyz="0 -0.027 -0.00775" rpy="0 0 0"/>
            <material name="black"/>
        </visual>

        <!-- corners -->
        <visual>
            <geometry>
                <cylinder radius="0.0126" length="0.0237"/>
            </geometry>
            <origin xyz="0.0274 0.02445 0" rpy="0 0 0"/>
            <material name="black"/>        
        </visual>
        <visual>
            <geometry>
                <cylinder radius="0.0126" length="0.0237"/>
            </geometry>
            <origin xyz="-0.0274 0.02445 0" rpy="0 0 0"/>
            <material name="black"/>        
        </visual>
        <visual>
            <geometry>
                <cylinder radius="0.0126" length="0.0237"/>
            </geometry>
            <origin xyz="0.0274 -0.02445 0" rpy="0 0 0"/>
            <material name="black"/>        
        </visual>
        <visual>
            <geometry>
                <cylinder radius="0.0126" length="0.0237"/>
            </geometry>
            <origin xyz="-0.0274 -0.02445 0" rpy="0 0 0"/>
            <material name="black"/>        
        </visual>
    </link>


    <!-- body motors ////////////////////////////////////////////////////////////////////////////////// -->
    <!-- see motor_doubleu joints for rotation -->
    <joint name="body_base_sq_front_body_motor_joint" type="fixed">
        <parent link="body_base_sq_link"/>
        <child link="front_body_motor_link"/>
        <origin xyz="0.0355 0 -0.013" rpy="0 0 0"/>
    </joint>

    <link name="front_body_motor_link">
        <visual>
            <geometry>
                <box size="0.034 0.02 0.023"/>
            </geometry>
            <origin xyz="0 0 0" rpy="0 0 0"/>
            <material name="black"/>
        </visual>
    </link>

    <joint name="body_base_sq_rear_body_motor_joint" type="fixed">
        <parent link="body_base_sq_link"/>
        <child link="rear_body_motor_link"/>
        <origin xyz="-0.0355 0 -0.013" rpy="0 0 0"/>
    </joint>

    <link name="rear_body_motor_link">
        <visual>
            <geometry>
                <box size="0.034 0.02 0.023"/>
            </geometry>
            <origin xyz="0 0 0" rpy="0 0 0"/>
            <material name="black"/>
        </visual>
    </link>

    <joint name="body_base_sq_left_body_motor_joint" type="fixed">
        <parent link="body_base_sq_link"/>
        <child link="left_body_motor_link"/>
        <origin xyz="0 0.0355 -0.013" rpy="0 0 0"/>
    </joint>

    <link name="left_body_motor_link">
        <visual>
            <geometry>
                <box size="0.02 0.034 0.023"/>
            </geometry>
            <origin xyz="0 0 0" rpy="0 0 0"/>
            <material name="black"/>
        </visual>
    </link>

    <joint name="body_base_sq_right_body_motor_joint" type="fixed">
        <parent link="body_base_sq_link"/>
        <child link="right_body_motor_link"/>
        <origin xyz="0 -0.0355 -0.013" rpy="0 0 0"/>
    </joint>

    <link name="right_body_motor_link">
        <visual>
            <geometry>
                <box size="0.02 0.034 0.023"/>
            </geometry>
            <origin xyz="0 0 0" rpy="0 0 0"/>
            <material name="black"/>
        </visual>
    </link>


    <!-- doubleU connectors ////////////////////////////////////////////////////////////////////////////////// -->
    <!-- center of joint rotation is set to be center of the body_base (top base) vertically 
         and center of the corner section horizontally as if centered around where the horn would be,
         the rest of the link is offset from there -->
    <!-- front doubleU ///////////////////////////////////////// -->
    <joint name="front_body_motor_front_doubleu_joint" type="continuous">
        <parent link="front_body_motor_link"/>
        <child link="front_doubleu_link"/>
        <origin xyz="0.0075 0 0.013" rpy="0 0 0"/>
        <axis xyz="0 0 -1"/>
    </joint>

    <!-- doubleu link is 0.0562 x 0.0334 x 0.0334 overall -->
    <link name="front_doubleu_link">
        <!-- horizontal components -->
        <visual>
            <geometry>
                <cylinder radius="0.01" length="0.0022"/>
            </geometry>
            <origin xyz="0 0 0.0026" rpy="0 0 0"/>
            <material name="green"/>    
        </visual>
        <visual>
            <geometry>
                <box size="0.0181 0.02 0.0022"/>
            </geometry>
            <origin xyz="0.00905 0 0.0026" rpy="0 0 0"/>
            <material name="green"/>
        </visual>
        <visual>
            <geometry>
                <cylinder radius="0.01" length="0.0022"/>
            </geometry>
            <origin xyz="0 0 -0.0286" rpy="0 0 0"/>
            <material name="green"/>    
        </visual>
        <visual>
            <geometry>
                <box size="0.0181 0.02 0.0022"/>
            </geometry>
            <origin xyz="0.00905 0 -0.0286" rpy="0 0 0"/>
            <material name="green"/>
        </visual>

        <!-- central component -->
        <visual>
            <geometry>
                <box size="0.0022 0.02 0.0334"/>
            </geometry>
            <origin xyz="0.0181 0 -0.013" rpy="0 0 0"/>
            <material name="green"/>
        </visual>
        <visual>
            <geometry>
                <box size="0.0022 0.0334 0.02"/>
            </geometry>
            <origin xyz="0.0181 0 -0.013" rpy="0 0 0"/>
            <material name="green"/>
        </visual>

        <!-- vertical  -->
        <visual>
            <geometry>
                <cylinder radius="0.01" length="0.0022"/>
            </geometry>
            <origin xyz="0.0362 0.0156 -0.013" rpy="1.5708 0 0"/>
            <material name="green"/>    
        </visual>
        <visual>
            <geometry>
                <box size="0.0181 0.0022 0.02"/>
            </geometry>
            <origin xyz="0.02715 0.0156 -0.013" rpy="0 0 0"/>
            <material name="green"/>
        </visual>
        <visual>
            <geometry>
                <cylinder radius="0.01" length="0.0022"/>
            </geometry>
            <origin xyz="0.0362 -0.0156 -0.013" rpy="-1.5708 0 0"/>
            <material name="green"/>    
        </visual>
        <visual>
            <geometry>
                <box size="0.0181 0.0022 0.02"/>
            </geometry>
            <origin xyz="0.02715 -0.0156 -0.013" rpy="0 0 0"/>
            <material name="green"/>
        </visual>
    </link>

    <!-- rear doubleU ///////////////////////////////////////// -->
    <joint name="rear_body_motor_rear_doubleu_joint" type="continuous">
        <parent link="rear_body_motor_link"/>
        <child link="rear_doubleu_link"/>
        <origin xyz="-0.0075 0 0.013" rpy="0 0 0"/>
        <axis xyz="0 0 -1"/>
    </joint>

    <!-- doubleu link is 0.0562 x 0.0334 x 0.0334 overall -->
    <link name="rear_doubleu_link">
        <!-- horizontal components -->
        <visual>
            <geometry>
                <cylinder radius="0.01" length="0.0022"/>
            </geometry>
            <origin xyz="0 0 0.0026" rpy="0 0 0"/>
            <material name="green"/>    
        </visual>
        <visual>
            <geometry>
                <box size="0.0181 0.02 0.0022"/>
            </geometry>
            <origin xyz="-0.00905 0 0.0026" rpy="0 0 0"/>
            <material name="green"/>
        </visual>
        <visual>
            <geometry>
                <cylinder radius="0.01" length="0.0022"/>
            </geometry>
            <origin xyz="0 0 -0.0286" rpy="0 0 0"/>
            <material name="green"/>    
        </visual>
        <visual>
            <geometry>
                <box size="0.0181 0.02 0.0022"/>
            </geometry>
            <origin xyz="-0.00905 0 -0.0286" rpy="0 0 0"/>
            <material name="green"/>
        </visual>

        <!-- central component -->
        <visual>
            <geometry>
                <box size="0.0022 0.02 0.0334"/>
            </geometry>
            <origin xyz="-0.0181 0 -0.013" rpy="0 0 0"/>
            <material name="green"/>
        </visual>
        <visual>
            <geometry>
                <box size="0.0022 0.0334 0.02"/>
            </geometry>
            <origin xyz="-0.0181 0 -0.013" rpy="0 0 0"/>
            <material name="green"/>
        </visual>

        <!-- vertical  -->
        <visual>
            <geometry>
                <cylinder radius="0.01" length="0.0022"/>
            </geometry>
            <origin xyz="-0.0362 0.0156 -0.013" rpy="1.5708 0 0"/>
            <material name="green"/>    
        </visual>
        <visual>
            <geometry>
                <box size="0.0181 0.0022 0.02"/>
            </geometry>
            <origin xyz="-0.02715 0.0156 -0.013" rpy="0 0 0"/>
            <material name="green"/>
        </visual>
        <visual>
            <geometry>
                <cylinder radius="0.01" length="0.0022"/>
            </geometry>
            <origin xyz="-0.0362 -0.0156 -0.013" rpy="-1.5708 0 0"/>
            <material name="green"/>    
        </visual>
        <visual>
            <geometry>
                <box size="0.0181 0.0022 0.02"/>
            </geometry>
            <origin xyz="-0.02715 -0.0156 -0.013" rpy="0 0 0"/>
            <material name="green"/>
        </visual>
    </link>

    <!-- left doubleU ///////////////////////////////////////// -->
    <joint name="left_body_motor_left_doubleu_joint" type="continuous">
        <parent link="left_body_motor_link"/>
        <child link="left_doubleu_link"/>
        <origin xyz="0 0.0075 0.013" rpy="0 0 0"/>
        <axis xyz="0 0 -1"/>
    </joint>

    <!-- doubleu link is 0.0562 x 0.0334 x 0.0334 overall -->
    <link name="left_doubleu_link">
        <!-- horizontal components -->
        <visual>
            <geometry>
                <cylinder radius="0.01" length="0.0022"/>
            </geometry>
            <origin xyz="0 0 0.0026" rpy="0 0 0"/>
            <material name="green"/>    
        </visual>
        <visual>
            <geometry>
                <box size="0.02 0.0181 0.0022"/>
            </geometry>
            <origin xyz="0 0.00905 0.0026" rpy="0 0 0"/>
            <material name="green"/>
        </visual>
        <visual>
            <geometry>
                <cylinder radius="0.01" length="0.0022"/>
            </geometry>
            <origin xyz="0 0 -0.0286" rpy="0 0 0"/>
            <material name="green"/>    
        </visual>
        <visual>
            <geometry>
                <box size="0.02 0.0181 0.0022"/>
            </geometry>
            <origin xyz="0 0.00905 -0.0286" rpy="0 0 0"/>
            <material name="green"/>
        </visual>

        <!-- central component -->
        <visual>
            <geometry>
                <box size="0.02 0.0022 0.0334"/>
            </geometry>
            <origin xyz="0 0.0181 -0.013" rpy="0 0 0"/>
            <material name="green"/>
        </visual>
        <visual>
            <geometry>
                <box size="0.0334 0.0022 0.02"/>
            </geometry>
            <origin xyz="0 0.0181 -0.013" rpy="0 0 0"/>
            <material name="green"/>
        </visual>

        <!-- vertical  -->
        <visual>
            <geometry>
                <cylinder radius="0.01" length="0.0022"/>
            </geometry>
            <origin xyz="0.0156 0.0362 -0.013" rpy="0 1.5708 0"/>
            <material name="green"/>    
        </visual>
        <visual>
            <geometry>
                <box size="0.0022 0.0181 0.02"/>
            </geometry>
            <origin xyz="0.0156 0.02715 -0.013" rpy="0 0 0"/>
            <material name="green"/>
        </visual>
        <visual>
            <geometry>
                <cylinder radius="0.01" length="0.0022"/>
            </geometry>
            <origin xyz="-0.0156 0.0362 -0.013" rpy="0 -1.5708 0"/>
            <material name="green"/>    
        </visual>
        <visual>
            <geometry>
                <box size="0.0022 0.0181 0.02"/>
            </geometry>
            <origin xyz="-0.0156 0.02715 -0.013" rpy="0 0 0"/>
            <material name="green"/>
        </visual>
    </link>

    <!-- right doubleU ///////////////////////////////////////// -->
    <joint name="right_body_motor_right_doubleu_joint" type="continuous">
        <parent link="right_body_motor_link"/>
        <child link="right_doubleu_link"/>
        <origin xyz="0 -0.0075 0.013" rpy="0 0 0"/>
        <axis xyz="0 0 -1"/>
    </joint>

    <!-- doubleu link is 0.0562 x 0.0334 x 0.0334 overall -->
    <link name="right_doubleu_link">
        <!-- horizontal components -->
        <visual>
            <geometry>
                <cylinder radius="0.01" length="0.0022"/>
            </geometry>
            <origin xyz="0 0 0.0026" rpy="0 0 0"/>
            <material name="green"/>    
        </visual>
        <visual>
            <geometry>
                <box size="0.02 0.0181 0.0022"/>
            </geometry>
            <origin xyz="0 -0.00905 0.0026" rpy="0 0 0"/>
            <material name="green"/>
        </visual>
        <visual>
            <geometry>
                <cylinder radius="0.01" length="0.0022"/>
            </geometry>
            <origin xyz="0 0 -0.0286" rpy="0 0 0"/>
            <material name="green"/>    
        </visual>
        <visual>
            <geometry>
                <box size="0.02 0.0181 0.0022"/>
            </geometry>
            <origin xyz="0 -0.00905 -0.0286" rpy="0 0 0"/>
            <material name="green"/>
        </visual>

        <!-- central component -->
        <visual>
            <geometry>
                <box size="0.02 0.0022 0.0334"/>
            </geometry>
            <origin xyz="0 -0.0181 -0.013" rpy="0 0 0"/>
            <material name="green"/>
        </visual>
        <visual>
            <geometry>
                <box size="0.0334 0.0022 0.02"/>
            </geometry>
            <origin xyz="0 -0.0181 -0.013" rpy="0 0 0"/>
            <material name="green"/>
        </visual>

        <!-- vertical  -->
        <visual>
            <geometry>
                <cylinder radius="0.01" length="0.0022"/>
            </geometry>
            <origin xyz="0.0156 -0.0362 -0.013" rpy="0 1.5708 0"/>
            <material name="green"/>    
        </visual>
        <visual>
            <geometry>
                <box size="0.0022 0.0181 0.02"/>
            </geometry>
            <origin xyz="0.0156 -0.02715 -0.013" rpy="0 0 0"/>
            <material name="green"/>
        </visual>
        <visual>
            <geometry>
                <cylinder radius="0.01" length="0.0022"/>
            </geometry>
            <origin xyz="-0.0156 -0.0362 -0.013" rpy="0 -1.5708 0"/>
            <material name="green"/>    
        </visual>
        <visual>
            <geometry>
                <box size="0.0022 0.0181 0.02"/>
            </geometry>
            <origin xyz="-0.0156 -0.02715 -0.013" rpy="0 0 0"/>
            <material name="green"/>
        </visual>
    </link>


    <!-- thigh motors ////////////////////////////////////////////////////////////////////////////////// -->
    <!-- center of joint rotation is set to be horizontally centerer of the outer most rounded end part of the 
         doubleu on the clockwise side when viewed from above,
         the rest of the link is offset from there -->
    <joint name="front_doubleu_front_thigh_motor_joint" type="continuous">
        <parent link="front_doubleu_link"/>
        <child link="front_thigh_motor_link"/>
        <origin xyz="0.0362 -0.0156 -0.013" rpy="0 0 0"/>
        <axis xyz="0 1 0"/>
    </joint>

    <link name="front_thigh_motor_link">
        <visual>
            <geometry>
                <box size="0.034 0.023 0.02"/>
            </geometry>
            <origin xyz="0.0075 0.0156 0" rpy="0 0 0"/>
            <material name="black"/>
        </visual>
    </link>

    <joint name="rear_doubleu_rear_thigh_motor_joint" type="continuous">
        <parent link="rear_doubleu_link"/>
        <child link="rear_thigh_motor_link"/>
        <origin xyz="-0.0362 -0.0156 -0.013" rpy="0 0 0"/>
        <axis xyz="0 -1 0"/>
    </joint>

    <link name="rear_thigh_motor_link">
        <visual>
            <geometry>
                <box size="0.034 0.023 0.02"/>
            </geometry>
            <origin xyz="-0.0075 0.0156 0" rpy="0 0 0"/>
            <material name="black"/>
        </visual>
    </link>

    <joint name="left_doubleu_left_thigh_motor_joint" type="continuous">
        <parent link="left_doubleu_link"/>
        <child link="left_thigh_motor_link"/>
        <origin xyz="-0.0156 0.0362 -0.013" rpy="0 0 0"/>
        <axis xyz="-1 0 0"/>
    </joint>

    <link name="left_thigh_motor_link">
        <visual>
            <geometry>
                <box size="0.023 0.034 0.02"/>
            </geometry>
            <origin xyz="0.0156 0.0075 0" rpy="0 0 0"/>
            <material name="black"/>
        </visual>
    </link>

    <joint name="right_doubleu_right_thigh_motor_joint" type="continuous">
        <parent link="right_doubleu_link"/>
        <child link="right_thigh_motor_link"/>
        <origin xyz="-0.0156 -0.0362 -0.013" rpy="0 0 0"/>
        <axis xyz="1 0 0"/>
    </joint>

    <link name="right_thigh_motor_link">
        <visual>
            <geometry>
                <box size="0.023 0.034 0.02"/>
            </geometry>
            <origin xyz="0.0156 -0.0075 0" rpy="0 0 0"/>
            <material name="black"/>
        </visual>
    </link>


    <!-- sides ////////////////////////////////////////////////////////////////////////////////// -->
    <!-- joint origin is set for center of side in direction towards leg, and center of motor in cw/ccw directions when viewed from above
         (note motor links are around rotation center, so motor body centers are offset) -->
    <joint name="front_thigh_motor_front_side_joint" type="fixed">
        <parent link="front_thigh_motor_link"/>
        <child link="front_side_link"/>
        <origin xyz="0.0255 0.0156 0" rpy="0 0 0"/>
    </joint>

    <link name="front_side_link">
        <visual>
            <geometry>
                <box size="0.072 0.0022 0.02"/>
            </geometry>
            <origin xyz="0 0.0126 0" rpy="0 0 0"/>
            <material name="blue"/>
        </visual>
        <visual>
            <geometry>
                <box size="0.072 0.0022 0.02"/>
            </geometry>
            <origin xyz="0 -0.0126 0" rpy="0 0 0"/>
            <material name="blue"/>
        </visual>
    </link>

    <joint name="rear_thigh_motor_rear_side_joint" type="fixed">
        <parent link="rear_thigh_motor_link"/>
        <child link="rear_side_link"/>
        <origin xyz="-0.0255 0.0156 0" rpy="0 0 0"/>
    </joint>

    <link name="rear_side_link">
        <visual>
            <geometry>
                <box size="0.072 0.0022 0.02"/>
            </geometry>
            <origin xyz="0 0.0126 0" rpy="0 0 0"/>
            <material name="blue"/>
        </visual>
        <visual>
            <geometry>
                <box size="0.072 0.0022 0.02"/>
            </geometry>
            <origin xyz="0 -0.0126 0" rpy="0 0 0"/>
            <material name="blue"/>
        </visual>
    </link>

    <joint name="left_thigh_motor_left_side_joint" type="fixed">
        <parent link="left_thigh_motor_link"/>
        <child link="left_side_link"/>
        <origin xyz="0.0156 0.0255 0" rpy="0 0 0"/>
    </joint>

    <link name="left_side_link">
        <visual>
            <geometry>
                <box size="0.0022 0.072 0.02"/>
            </geometry>
            <origin xyz="0.0126 0 0" rpy="0 0 0"/>
            <material name="blue"/>
        </visual>
        <visual>
            <geometry>
                <box size="0.0022 0.072 0.02"/>
            </geometry>
            <origin xyz="-0.0126 0 0" rpy="0 0 0"/>
            <material name="blue"/>
        </visual>
    </link>

    <joint name="right_thigh_motor_right_side_joint" type="fixed">
        <parent link="right_thigh_motor_link"/>
        <child link="right_side_link"/>
        <origin xyz="0.0156 -0.0255 0" rpy="0 0 0"/>
    </joint>

    <link name="right_side_link">
        <visual>
            <geometry>
                <box size="0.0022 0.072 0.02"/>
            </geometry>
            <origin xyz="0.0126 0 0" rpy="0 0 0"/>
            <material name="blue"/>
        </visual>
        <visual>
            <geometry>
                <box size="0.0022 0.072 0.02"/>
            </geometry>
            <origin xyz="-0.0126 0 0" rpy="0 0 0"/>
            <material name="blue"/>
        </visual>
    </link>


    <!-- leg motors ////////////////////////////////////////////////////////////////////////////////// -->
    <!-- see motor_leg joints for rotation -->
    <joint name="front_side_front_leg_motor_joint" type="fixed">
        <parent link="front_side_link"/>
        <child link="front_leg_motor_link"/>
        <origin xyz="0.018 0 0" rpy="0 0 0"/>
    </joint>

    <link name="front_leg_motor_link">
        <visual>
            <geometry>
                <box size="0.034 0.023 0.02"/>
            </geometry>
            <origin xyz="0 0 0" rpy="0 0 0"/>
            <material name="black"/>
        </visual>
    </link>

    <joint name="rear_side_rear_leg_motor_joint" type="fixed">
        <parent link="rear_side_link"/>
        <child link="rear_leg_motor_link"/>
        <origin xyz="-0.018 0 0" rpy="0 0 0"/>
    </joint>

    <link name="rear_leg_motor_link">
        <visual>
            <geometry>
                <box size="0.034 0.023 0.02"/>
            </geometry>
            <origin xyz="0 0 0" rpy="0 0 0"/>
            <material name="black"/>
        </visual>
    </link>

    <joint name="left_side_left_leg_motor_joint" type="fixed">
        <parent link="left_side_link"/>
        <child link="left_leg_motor_link"/>
        <origin xyz="0 0.018 0" rpy="0 0 0"/>
    </joint>

    <link name="left_leg_motor_link">
        <visual>
            <geometry>
                <box size="0.023 0.034 0.02"/>
            </geometry>
            <origin xyz="0 0 0" rpy="0 0 0"/>
            <material name="black"/>
        </visual>
    </link>

    <joint name="right_side_right_leg_motor_joint" type="fixed">
        <parent link="right_side_link"/>
        <child link="right_leg_motor_link"/>
        <origin xyz="0 -0.018 0" rpy="0 0 0"/>
    </joint>

    <link name="right_leg_motor_link">
        <visual>
            <geometry>
                <box size="0.023 0.034 0.02"/>
            </geometry>
            <origin xyz="0 0 0" rpy="0 0 0"/>
            <material name="black"/>
        </visual>
    </link>


    <!-- legs ////////////////////////////////////////////////////////////////////////////////// -->
    <!-- center of joint rotation is set to be center of the clockwise side_link horizontally when viewed from above and inline with the motor drive,
         the rest of the link is offset from there -->
    <!-- front leg ///////////////////////////////////////// -->
    <joint name="front_leg_motor_front_leg_joint" type="continuous">
        <parent link="front_leg_motor_link"/>
        <child link="front_leg_link"/>
        <origin xyz="0.0075 -0.0126 0" rpy="0 0 0"/>
        <axis xyz="0 1 0"/>
    </joint>

    <link name="front_leg_link">
        <!-- top straight pieces -->
        <visual>
            <geometry>
                <box size="0.01 0.0022 0.0242"/>
            </geometry>
            <origin xyz="0 -0.003 0.0219" rpy="0 0 0"/>
            <material name="green"/>
        </visual>
        <visual>
            <geometry>
                <box size="0.01 0.0022 0.0242"/>
            </geometry>
            <origin xyz="0 0.0282 0.0219" rpy="0 0 0"/>
            <material name="green"/>
        </visual>

        <!-- top diagonals -->
        <visual>
            <geometry>
                <box size="0.005 0.0022 0.0247"/>
            </geometry>
            <origin xyz="-0.0052 -0.003 0.0214" rpy="0 0.1923 0"/>
            <material name="green"/>
        </visual>
        <visual>
            <geometry>
                <box size="0.005 0.0022 0.0247"/>
            </geometry>
            <origin xyz="0.0052 -0.003 0.0214" rpy="0 -0.1923 0"/>
            <material name="green"/>
        </visual>
        <visual>
            <geometry>
                <box size="0.005 0.0022 0.0247"/>
            </geometry>
            <origin xyz="-0.0052 0.0282 0.0214" rpy="0 0.1923 0"/>
            <material name="green"/>
        </visual>
        <visual>
            <geometry>
                <box size="0.005 0.0022 0.0247"/>
            </geometry>
            <origin xyz="0.0052 0.0282 0.0214" rpy="0 -0.1923 0"/>
            <material name="green"/>
        </visual>

        <!-- center side pieces -->
        <visual>
            <geometry>
                <box size="0.02 0.0022 0.081"/>
            </geometry>
            <origin xyz="0 -0.003 -0.0307" rpy="0 0 0"/>
            <material name="green"/>
        </visual>
        <visual>
            <geometry>
                <box size="0.02 0.0022 0.081"/>
            </geometry>
            <origin xyz="0 0.0282 -0.0307" rpy="0 0 0"/>
            <material name="green"/>
        </visual>

        <!-- cross beams -->
        <visual>
            <geometry>
                <box size="0.02 0.0334 0.0022"/>
            </geometry>
            <origin xyz="0 0.0126 -0.0438" rpy="0 0 0"/>
            <material name="green"/>
        </visual>
        <visual>
            <geometry>
                <box size="0.02 0.0334 0.0049"/>
            </geometry>
            <origin xyz="0 0.0126 -0.0663" rpy="0 0 0"/>
            <material name="green"/>
        </visual>

        <!-- lower side pieces -->
        <visual>
            <geometry>
                <box size="0.02 0.0025 0.0139"/>
            </geometry>
            <origin xyz="0 -0.00535 -0.06325" rpy="0 0 0"/>
            <material name="green"/>
        </visual>
        <visual>
            <geometry>
                <box size="0.02 0.0025 0.0139"/>
            </geometry>
            <origin xyz="0 0.03055 -0.06325" rpy="0 0 0"/>
            <material name="green"/>
        </visual>

        <!-- bottom diagonals -->
        <visual>
            <geometry>
                <box size="0.02 0.0022 0.0207"/>
            </geometry>
            <origin xyz="0 0.00127 -0.0767" rpy="0.76 0 0"/>
            <material name="green"/>
        </visual>
        <visual>
            <geometry>
                <box size="0.02 0.0022 0.0207"/>
            </geometry>
            <origin xyz="0 0.02393 -0.0767" rpy="-0.76 0 0"/>
            <material name="green"/>
        </visual>

        <!-- bottom horizontal -->
        <visual>
            <geometry>
                <box size="0.02 0.0099 0.0022"/>
            </geometry>
            <origin xyz="0 0.0126 -0.0839" rpy="0 0 0"/>
            <material name="green"/>
        </visual>
    </link>

    <!-- rear leg ///////////////////////////////////////// -->
    <joint name="rear_leg_motor_rear_leg_joint" type="continuous">
        <parent link="rear_leg_motor_link"/>
        <child link="rear_leg_link"/>
        <origin xyz="-0.0075 -0.0126 0" rpy="0 0 0"/>
        <axis xyz="0 -1 0"/>
    </joint>

    <link name="rear_leg_link">
        <!-- top straight pieces -->
        <visual>
            <geometry>
                <box size="0.01 0.0022 0.0242"/>
            </geometry>
            <origin xyz="0 -0.003 0.0219" rpy="0 0 0"/>
            <material name="green"/>
        </visual>
        <visual>
            <geometry>
                <box size="0.01 0.0022 0.0242"/>
            </geometry>
            <origin xyz="0 0.0282 0.0219" rpy="0 0 0"/>
            <material name="green"/>
        </visual>

        <!-- top diagonals -->
        <visual>
            <geometry>
                <box size="0.005 0.0022 0.0247"/>
            </geometry>
            <origin xyz="0.0052 -0.003 0.0214" rpy="0 -0.1923 0"/>
            <material name="green"/>
        </visual>
        <visual>
            <geometry>
                <box size="0.005 0.0022 0.0247"/>
            </geometry>
            <origin xyz="-0.0052 -0.003 0.0214" rpy="0 0.1923 0"/>
            <material name="green"/>
        </visual>
        <visual>
            <geometry>
                <box size="0.005 0.0022 0.0247"/>
            </geometry>
            <origin xyz="0.0052 0.0282 0.0214" rpy="0 -0.1923 0"/>
            <material name="green"/>
        </visual>
        <visual>
            <geometry>
                <box size="0.005 0.0022 0.0247"/>
            </geometry>
            <origin xyz="-0.0052 0.0282 0.0214" rpy="0 0.1923 0"/>
            <material name="green"/>
        </visual>

        <!-- center side pieces -->
        <visual>
            <geometry>
                <box size="0.02 0.0022 0.081"/>
            </geometry>
            <origin xyz="0 -0.003 -0.0307" rpy="0 0 0"/>
            <material name="green"/>
        </visual>
        <visual>
            <geometry>
                <box size="0.02 0.0022 0.081"/>
            </geometry>
            <origin xyz="0 0.0282 -0.0307" rpy="0 0 0"/>
            <material name="green"/>
        </visual>

        <!-- cross beams -->
        <visual>
            <geometry>
                <box size="0.02 0.0334 0.0022"/>
            </geometry>
            <origin xyz="0 0.0126 -0.0438" rpy="0 0 0"/>
            <material name="green"/>
        </visual>
        <visual>
            <geometry>
                <box size="0.02 0.0334 0.0049"/>
            </geometry>
            <origin xyz="0 0.0126 -0.0663" rpy="0 0 0"/>
            <material name="green"/>
        </visual>

        <!-- lower side pieces -->
        <visual>
            <geometry>
                <box size="0.02 0.0025 0.0139"/>
            </geometry>
            <origin xyz="0 -0.00535 -0.06325" rpy="0 0 0"/>
            <material name="green"/>
        </visual>
        <visual>
            <geometry>
                <box size="0.02 0.0025 0.0139"/>
            </geometry>
            <origin xyz="0 0.03055 -0.06325" rpy="0 0 0"/>
            <material name="green"/>
        </visual>

        <!-- bottom diagonals -->
        <visual>
            <geometry>
                <box size="0.02 0.0022 0.0207"/>
            </geometry>
            <origin xyz="0 0.00127 -0.0767" rpy="0.76 0 0"/>
            <material name="green"/>
        </visual>
        <visual>
            <geometry>
                <box size="0.02 0.0022 0.0207"/>
            </geometry>
            <origin xyz="0 0.02393 -0.0767" rpy="-0.76 0 0"/>
            <material name="green"/>
        </visual>

        <!-- bottom horizontal -->
        <visual>
            <geometry>
                <box size="0.02 0.0099 0.0022"/>
            </geometry>
            <origin xyz="0 0.0126 -0.0839" rpy="0 0 0"/>
            <material name="green"/>
        </visual>
    </link>

    <!-- left leg ///////////////////////////////////////// -->
    <joint name="left_leg_motor_left_leg_joint" type="continuous">
        <parent link="left_leg_motor_link"/>
        <child link="left_leg_link"/>
        <origin xyz="-0.0126 0.0075 0" rpy="0 0 0"/>
        <axis xyz="-1 0 0"/>
    </joint>

    <link name="left_leg_link">
        <!-- top straight pieces -->
        <visual>
            <geometry>
                <box size="0.0022 0.01 0.0242"/>
            </geometry>
            <origin xyz="-0.003 0 0.0219" rpy="0 0 0"/>
            <material name="green"/>
        </visual>
        <visual>
            <geometry>
                <box size="0.0022 0.01 0.0242"/>
            </geometry>
            <origin xyz="0.0282 0 0.0219" rpy="0 0 0"/>
            <material name="green"/>
        </visual>

        <!-- top diagonals -->
        <visual>
            <geometry>
                <box size="0.0022 0.005 0.0247"/>
            </geometry>
            <origin xyz="-0.003 -0.0052 0.0214" rpy="-0.1923 0 0"/>
            <material name="green"/>
        </visual>
        <visual>
            <geometry>
                <box size="0.0022 0.005 0.0247"/>
            </geometry>
            <origin xyz="-0.003 0.0052 0.0214" rpy="0.1923 0 0"/>
            <material name="green"/>
        </visual>
        <visual>
            <geometry>
                <box size="0.0022 0.005 0.0247"/>
            </geometry>
            <origin xyz="0.0282 -0.0052 0.0214" rpy="-0.1923 0 0"/>
            <material name="green"/>
        </visual>
        <visual>
            <geometry>
                <box size="0.0022 0.005 0.0247"/>
            </geometry>
            <origin xyz="0.0282 0.0052 0.0214" rpy="0.1923 0 0"/>
            <material name="green"/>
        </visual>

        <!-- center side pieces -->
        <visual>
            <geometry>
                <box size="0.0022 0.02 0.081"/>
            </geometry>
            <origin xyz="-0.003 0 -0.0307" rpy="0 0 0"/>
            <material name="green"/>
        </visual>
        <visual>
            <geometry>
                <box size="0.0022 0.02 0.081"/>
            </geometry>
            <origin xyz="0.0282 0 -0.0307" rpy="0 0 0"/>
            <material name="green"/>
        </visual>

        <!-- cross beams -->
        <visual>
            <geometry>
                <box size="0.0334 0.02 0.0022"/>
            </geometry>
            <origin xyz="0.0126 0 -0.0438" rpy="0 0 0"/>
            <material name="green"/>
        </visual>
        <visual>
            <geometry>
                <box size="0.0334 0.02 0.0049"/>
            </geometry>
            <origin xyz="0.0126 0 -0.0663" rpy="0 0 0"/>
            <material name="green"/>
        </visual>

        <!-- lower side pieces -->
        <visual>
            <geometry>
                <box size="0.0025 0.02 0.0139"/>
            </geometry>
            <origin xyz="-0.00535 0 -0.06325" rpy="0 0 0"/>
            <material name="green"/>
        </visual>
        <visual>
            <geometry>
                <box size="0.0025 0.02 0.0139"/>
            </geometry>
            <origin xyz="0.03055 0 -0.06325" rpy="0 0 0"/>
            <material name="green"/>
        </visual>

        <!-- bottom diagonals -->
        <visual>
            <geometry>
                <box size="0.0022 0.02 0.0207"/>
            </geometry>
            <origin xyz="0.00127 0 -0.0767" rpy="0 -0.76 0"/>
            <material name="green"/>
        </visual>
        <visual>
            <geometry>
                <box size="0.0022 0.02 0.0207"/>
            </geometry>
            <origin xyz="0.02393 0 -0.0767" rpy="0 0.76 0"/>
            <material name="green"/>
        </visual>

        <!-- bottom horizontal -->
        <visual>
            <geometry>
                <box size="0.0099 0.02 0.0022"/>
            </geometry>
            <origin xyz="0.0126 0 -0.0839" rpy="0 0 0"/>
            <material name="green"/>
        </visual>
    </link>

    <!-- right leg ///////////////////////////////////////// -->
    <joint name="right_leg_motor_right_leg_joint" type="continuous">
        <parent link="right_leg_motor_link"/>
        <child link="right_leg_link"/>
        <origin xyz="-0.0126 -0.0075 0" rpy="0 0 0"/>
        <axis xyz="1 0 0"/>
    </joint>

    <link name="right_leg_link">
        <!-- top straight pieces -->
        <visual>
            <geometry>
                <box size="0.0022 0.01 0.0242"/>
            </geometry>
            <origin xyz="-0.003 0 0.0219" rpy="0 0 0"/>
            <material name="green"/>
        </visual>
        <visual>
            <geometry>
                <box size="0.0022 0.01 0.0242"/>
            </geometry>
            <origin xyz="0.0282 0 0.0219" rpy="0 0 0"/>
            <material name="green"/>
        </visual>

        <!-- top diagonals -->
        <visual>
            <geometry>
                <box size="0.0022 0.005 0.0247"/>
            </geometry>
            <origin xyz="-0.003 0.0052 0.0214" rpy="0.1923 0 0"/>
            <material name="green"/>
        </visual>
        <visual>
            <geometry>
                <box size="0.0022 0.005 0.0247"/>
            </geometry>
            <origin xyz="-0.003 -0.0052 0.0214" rpy="-0.1923 0 0"/>
            <material name="green"/>
        </visual>
        <visual>
            <geometry>
                <box size="0.0022 0.005 0.0247"/>
            </geometry>
            <origin xyz="0.0282 0.0052 0.0214" rpy="0.1923 0 0"/>
            <material name="green"/>
        </visual>
        <visual>
            <geometry>
                <box size="0.0022 0.005 0.0247"/>
            </geometry>
            <origin xyz="0.0282 -0.0052 0.0214" rpy="-0.1923 0 0"/>
            <material name="green"/>
        </visual>

        <!-- center side pieces -->
        <visual>
            <geometry>
                <box size="0.0022 0.02 0.081"/>
            </geometry>
            <origin xyz="-0.003 0 -0.0307" rpy="0 0 0"/>
            <material name="green"/>
        </visual>
        <visual>
            <geometry>
                <box size="0.0022 0.02 0.081"/>
            </geometry>
            <origin xyz="0.0282 0 -0.0307" rpy="0 0 0"/>
            <material name="green"/>
        </visual>

        <!-- cross beams -->
        <visual>
            <geometry>
                <box size="0.0334 0.02 0.0022"/>
            </geometry>
            <origin xyz="0.0126 0 -0.0438" rpy="0 0 0"/>
            <material name="green"/>
        </visual>
        <visual>
            <geometry>
                <box size="0.0334 0.02 0.0049"/>
            </geometry>
            <origin xyz="0.0126 0 -0.0663" rpy="0 0 0"/>
            <material name="green"/>
        </visual>

        <!-- lower side pieces -->
        <visual>
            <geometry>
                <box size="0.0025 0.02 0.0139"/>
            </geometry>
            <origin xyz="-0.00535 0 -0.06325" rpy="0 0 0"/>
            <material name="green"/>
        </visual>
        <visual>
            <geometry>
                <box size="0.0025 0.02 0.0139"/>
            </geometry>
            <origin xyz="0.03055 0 -0.06325" rpy="0 0 0"/>
            <material name="green"/>
        </visual>

        <!-- bottom diagonals -->
        <visual>
            <geometry>
                <box size="0.0022 0.02 0.0207"/>
            </geometry>
            <origin xyz="0.00127 0 -0.0767" rpy="0 -0.76 0"/>
            <material name="green"/>
        </visual>
        <visual>
            <geometry>
                <box size="0.0022 0.02 0.0207"/>
            </geometry>
            <origin xyz="0.02393 0 -0.0767" rpy="0 0.76 0"/>
            <material name="green"/>
        </visual>

        <!-- bottom horizontal -->
        <visual>
            <geometry>
                <box size="0.0099 0.02 0.0022"/>
            </geometry>
            <origin xyz="0.0126 0 -0.0839" rpy="0 0 0"/>
            <material name="green"/>
        </visual>
    </link>
</robot>